<?xml version="1.0" ?>
<!-- =================================================================================== -->
<!-- |    This document was autogenerated by xacro from xarm_device.urdf.xacro         | -->
<!-- |    EDITING THIS FILE BY HAND IS NOT RECOMMENDED                                 | -->
<!-- =================================================================================== -->
<robot name="UF_ROBOT">
  <!-- Insert at the beginning of xarm_device_macro.xacro -->
  <material name="Black">
    <color rgba="0.0 0.0 0.0 1.0"/>
  </material>
  <material name="Red">
    <color rgba="0.8 0.0 0.0 1.0"/>
  </material>
  <material name="White">
    <color rgba="1.0 1.0 1.0 1.0"/>
  </material>
  <material name="Silver">
    <color rgba="0.753 0.753 0.753 1.0"/>
  </material>
  <link name="world"/>
  <joint name="world_joint" type="fixed">
    <parent link="world"/>
    <child link="link_base"/>
    <origin rpy="0 0 0" xyz="0 0 0"/>
  </joint>
  <ros2_control name="uf_robot_hardware/UFRobotSystemHardware" type="system">
    <hardware>
      <plugin>uf_robot_hardware/UFRobotSystemHardware</plugin>
      <param name="hw_ns">xarm</param>
      <param name="velocity_control">False</param>
      <param name="prefix">P</param>
      <param name="robot_ip">R192.168.1.156</param>
      <param name="report_type">normal</param>
      <param name="dof">6</param>
      <param name="baud_checkset">True</param>
      <param name="default_gripper_baud">2000000</param>
      <param name="robot_type">lite</param>
      <param name="add_gripper">True</param>
    </hardware>
    <joint name="joint1">
      <command_interface name="position">
        <param name="min">-6.283185307179586</param>
        <param name="max">6.283185307179586</param>
      </command_interface>
      <command_interface name="velocity">
        <param name="min">-3.14</param>
        <param name="max">3.14</param>
      </command_interface>
      <state_interface name="position"/>
      <state_interface name="velocity"/>
      <!-- <state_interface name="effort"/> -->
    </joint>
    <joint name="joint2">
      <command_interface name="position">
        <param name="min">-2.61799</param>
        <param name="max">2.61799</param>
      </command_interface>
      <command_interface name="velocity">
        <param name="min">-3.14</param>
        <param name="max">3.14</param>
      </command_interface>
      <state_interface name="position"/>
      <state_interface name="velocity"/>
      <!-- <state_interface name="effort"/> -->
    </joint>
    <joint name="joint3">
      <command_interface name="position">
        <param name="min">-0.061087</param>
        <param name="max">5.235988</param>
      </command_interface>
      <command_interface name="velocity">
        <param name="min">-3.14</param>
        <param name="max">3.14</param>
      </command_interface>
      <state_interface name="position"/>
      <state_interface name="velocity"/>
      <!-- <state_interface name="effort"/> -->
    </joint>
    <joint name="joint4">
      <command_interface name="position">
        <param name="min">-6.283185307179586</param>
        <param name="max">6.283185307179586</param>
      </command_interface>
      <command_interface name="velocity">
        <param name="min">-3.14</param>
        <param name="max">3.14</param>
      </command_interface>
      <state_interface name="position"/>
      <state_interface name="velocity"/>
      <!-- <state_interface name="effort"/> -->
    </joint>
    <joint name="joint5">
      <command_interface name="position">
        <param name="min">-2.1642</param>
        <param name="max">2.1642</param>
      </command_interface>
      <command_interface name="velocity">
        <param name="min">-3.14</param>
        <param name="max">3.14</param>
      </command_interface>
      <state_interface name="position"/>
      <state_interface name="velocity"/>
      <!-- <state_interface name="effort"/> -->
    </joint>
    <joint name="joint6">
      <command_interface name="position">
        <param name="min">-6.283185307179586</param>
        <param name="max">6.283185307179586</param>
      </command_interface>
      <command_interface name="velocity">
        <param name="min">-3.14</param>
        <param name="max">3.14</param>
      </command_interface>
      <state_interface name="position"/>
      <state_interface name="velocity"/>
      <!-- <state_interface name="effort"/> -->
    </joint>

    <!-- Add this joint to your existing ros2_control section -->

  <joint name="left_finger_joint">
    <command_interface name="position">
      <!-- allowable range: 0 rad (fully open) to ~0.8 rad (fully closed) -->
      <param name="min">0.0</param>
      <param name="max">0.8</param>
    </command_interface>
    <command_interface name="velocity">
      <!-- (optional) if you ever want to send fingerâ€speed commands -->
      <param name="min">-2.0</param>
      <param name="max">2.0</param>
    </command_interface>
    <state_interface name="position"/>
    <state_interface name="velocity"/>
  </joint>

  </ros2_control>
  <link name="link_base">
    <inertial>
      <origin rpy="0 0 0" xyz="-0.00829544579053192 3.26357432323433E-05 0.0631194584987089"/>
      <mass value="1.65393501783165"/>
      <inertia ixx="0" ixy="0" ixz="0" iyy="0" iyz="0" izz="0"/>
    </inertial>
    <visual>
      <geometry>
        <mesh filename="meshes/lite6/visual/base.stl"/>
      </geometry>
      <origin rpy="0 0 0" xyz="0 0 0"/>
      <material name="White"/>
    </visual>
    <collision>
      <geometry>
        <mesh filename="meshes/lite6/collision/base.stl"/>
      </geometry>
      <origin rpy="0 0 0" xyz="0 0 0"/>
    </collision>
  </link>
  <link name="link1">
    <inertial>
      <origin rpy="0 0 0" xyz="-0.00036 0.04195 -0.0025"/>
      <mass value="1.411"/>
      <inertia ixx="0.0014516400000000001" ixy="-1.24e-05" ixz="6.7e-06" iyy="0.0008872999999999999" iyz="-0.0001255" izz="0.00131993"/>
    </inertial>
    <visual>
      <geometry>
        <mesh filename="meshes/lite6/visual/link1.stl"/>
      </geometry>
      <origin rpy="0 0 0" xyz="0 0 0"/>
      <material name="White"/>
    </visual>
    <collision>
      <geometry>
        <mesh filename="meshes/lite6/collision/link1.stl"/>
      </geometry>
      <origin rpy="0 0 0" xyz="0 0 0"/>
    </collision>
  </link>
  <joint name="joint1" type="revolute">
    <origin rpy="0 0 0" xyz="0 0 0.2435"/>
    <parent link="link_base"/>
    <child link="link1"/>
    <axis xyz="0 0 1"/>
    <limit effort="50.0" lower="-6.283185307179586" upper="6.283185307179586" velocity="3.14"/>
    <dynamics damping="1.0" friction="1.0"/>
  </joint>
  <link name="link2">
    <inertial>
      <origin rpy="0 0 0" xyz="0.179 0.0 0.0584"/>
      <mass value="1.34"/>
      <inertia ixx="0.0015854" ixy="6.766e-06" ixz="0.00115136" iyy="0.0056097" iyz="-1.1399999999999999e-06" izz="0.00485"/>
    </inertial>
    <visual>
      <geometry>
        <mesh filename="meshes/lite6/visual/link2.stl"/>
      </geometry>
      <origin rpy="0 0 0" xyz="0 0 0"/>
      <material name="White"/>
    </visual>
    <collision>
      <geometry>
        <mesh filename="meshes/lite6/collision/link2.stl"/>
      </geometry>
      <origin rpy="0 0 0" xyz="0 0 0"/>
    </collision>
  </link>
  <joint name="joint2" type="revolute">
    <origin rpy="1.5708 -1.5708 3.1416" xyz="0 0 0"/>
    <parent link="link1"/>
    <child link="link2"/>
    <axis xyz="0 0 1"/>
    <limit effort="50.0" lower="-2.61799" upper="2.61799" velocity="3.14"/>
    <dynamics damping="1.0" friction="1.0"/>
  </joint>
  <link name="link3">
    <inertial>
      <origin rpy="0 0 0" xyz="0.072 -0.0357 -0.001"/>
      <mass value="0.953"/>
      <inertia ixx="0.0008861" ixy="0.00039286999999999997" ixz="-7.065999999999999e-05" iyy="0.0015784999999999998" iyz="2.4449999999999998e-05" izz="0.00184677"/>
    </inertial>
    <visual>
      <geometry>
        <mesh filename="meshes/lite6/visual/link3.stl"/>
      </geometry>
      <origin rpy="0 0 0" xyz="0 0 0"/>
      <material name="White"/>
    </visual>
    <collision>
      <geometry>
        <mesh filename="meshes/lite6/collision/link3.stl"/>
      </geometry>
      <origin rpy="0 0 0" xyz="0 0 0"/>
    </collision>
  </link>
  <joint name="joint3" type="revolute">
    <origin rpy="-3.1416 0 1.5708" xyz="0.2002 0 0"/>
    <parent link="link2"/>
    <child link="link3"/>
    <axis xyz="0 0 1"/>
    <limit effort="32.0" lower="-0.061087" upper="5.235988" velocity="3.14"/>
    <dynamics damping="1.0" friction="1.0"/>
  </joint>
  <link name="link4">
    <inertial>
      <origin rpy="0 0 0" xyz="-0.002 -0.0285 -0.0813"/>
      <mass value="1.284"/>
      <inertia ixx="0.003705" ixy="2e-06" ixz="-7.17e-06" iyy="0.0030455" iyz="0.00093188" izz="0.0015412999999999998"/>
    </inertial>
    <visual>
      <geometry>
        <mesh filename="meshes/lite6/visual/link4.stl"/>
      </geometry>
      <origin rpy="0 0 0" xyz="0 0 0"/>
      <material name="White"/>
    </visual>
    <collision>
      <geometry>
        <mesh filename="meshes/lite6/collision/link4.stl"/>
      </geometry>
      <origin rpy="0 0 0" xyz="0 0 0"/>
    </collision>
  </link>
  <joint name="joint4" type="revolute">
    <origin rpy="1.5708 0 0" xyz="0.087 -0.22761 0"/>
    <parent link="link3"/>
    <child link="link4"/>
    <axis xyz="0 0 1"/>
    <limit effort="32.0" lower="-6.283185307179586" upper="6.283185307179586" velocity="3.14"/>
    <dynamics damping="1.0" friction="1.0"/>
  </joint>
  <link name="link5">
    <inertial>
      <origin rpy="0 0 0" xyz="0.0 0.01 0.0019"/>
      <mass value="0.804"/>
      <inertia ixx="0.0005667999999999999" ixy="-6e-07" ixz="5.299999999999999e-06" iyy="0.0005076999999999999" iyz="4.8e-07" izz="0.00053"/>
    </inertial>
    <visual>
      <geometry>
        <mesh filename="meshes/lite6/visual/link5.stl"/>
      </geometry>
      <origin rpy="0 0 0" xyz="0 0 0"/>
      <material name="White"/>
    </visual>
    <collision>
      <geometry>
        <mesh filename="meshes/lite6/collision/link5.stl"/>
      </geometry>
      <origin rpy="0 0 0" xyz="0 0 0"/>
    </collision>
  </link>
  <joint name="joint5" type="revolute">
    <origin rpy="1.5708 0 0" xyz="0 0 0"/>
    <parent link="link4"/>
    <child link="link5"/>
    <axis xyz="0 0 1"/>
    <limit effort="32.0" lower="-2.1642" upper="2.1642" velocity="3.14"/>
    <dynamics damping="1.0" friction="1.0"/>
  </joint>
  <link name="link6">
    <inertial>
      <origin rpy="0 0 0" xyz="0.0 -0.00194 -0.0102"/>
      <mass value="0.13"/>
      <inertia ixx="7.726e-05" ixy="-1e-06" ixz="-4e-07" iyy="8.5665e-05" iyz="6e-07" izz="0.00014813999999999997"/>
    </inertial>
    <visual>
      <geometry>
        <mesh filename="meshes/lite6/visual/link6.stl"/>
      </geometry>
      <origin rpy="0 0 0" xyz="0 0 0"/>
      <material name="Silver"/>
    </visual>
    <collision>
      <geometry>
        <mesh filename="meshes/lite6/collision/link6.stl"/>
      </geometry>
      <origin rpy="0 0 0" xyz="0 0 0"/>
    </collision>
  </link>
  <joint name="joint6" type="revolute">
    <origin rpy="-1.5708 0 0" xyz="0 0.0625 0"/>
    <parent link="link5"/>
    <child link="link6"/>
    <axis xyz="0 0 1"/>
    <limit effort="20.0" lower="-6.283185307179586" upper="6.283185307179586" velocity="3.14"/>
    <dynamics damping="1.0" friction="1.0"/>
  </joint>
  <!-- <link name="gripper" />
    <joint name="${prefix}joint_eef" type="fixed">
      <origin xyz="0 0 0" rpy="0 0 0" />
      <parent link="${prefix}link6" />
      <child link="${prefix}link_eef" />
    </joint> -->
  <link name="base_link">
  <inertial>
    <origin xyz="0 0 0" rpy="0 0 0"/>
    <mass value="0.1"/>
    <inertia ixx="0.0001" ixy="0" ixz="0" iyy="0.0001" iyz="0" izz="0.0001"/>
  </inertial>
  <visual>
    <geometry>
      <mesh filename="meshes/gripper/base_link.STL"/>
    </geometry>
    <origin xyz="0 0 0" rpy="0 0 0"/>
    <material name="Gray"/>
  </visual>
  <collision>
    <geometry>
      <mesh filename="meshes/gripper/base_link.STL"/>
    </geometry>
    <origin xyz="0 0 0" rpy="0 0 0"/>
  </collision>
</link>

<!-- Joint connecting gripper base directly to robot's link6 -->
<joint name="joint_gripper" type="fixed">
  <parent link="link6"/>
  <child link="base_link"/>
  <origin xyz="0 0 0" rpy="0 0 0"/>
</joint>


<link name="left_outer_knuckle">
  <inertial>
    <origin xyz="0 0 0" rpy="0 0 0"/>
    <mass value="0.05"/>
    <inertia ixx="0.0001" ixy="0" ixz="0" iyy="0.0001" iyz="0" izz="0.0001"/>
  </inertial>
  <visual>
    <geometry>
      <mesh filename="meshes/gripper/left_outer_knuckle.STL"/>
    </geometry>
    <origin xyz="0 0 0" rpy="0 0 0"/>
    <material name="Gray"/>
  </visual>
  <collision>
    <geometry>
      <mesh filename="meshes/gripper/left_outer_knuckle.STL"/>
    </geometry>
    <origin xyz="0 0 0" rpy="0 0 0"/>
  </collision>
</link>

<!-- Left finger main joint (this is the actuated joint) -->
<joint name="left_finger_joint" type="revolute">
  <parent link="base_link"/>
  <child link="left_outer_knuckle"/>
  <origin xyz="0.04 0 0.06" rpy="0 0 0"/>  <!-- Adjust these values based on your gripper geometry -->
  <axis xyz="0 0 1"/>
  <limit effort="20.0" lower="0" upper="0.8" velocity="2.0"/>
  <dynamics damping="0.1" friction="0.1"/>
</joint>

<link name="left_inner_knuckle">
  <inertial>
    <origin xyz="0 0 0" rpy="0 0 0"/>
    <mass value="0.03"/>
    <inertia ixx="0.0001" ixy="0" ixz="0" iyy="0.0001" iyz="0" izz="0.0001"/>
  </inertial>
  <visual>
    <geometry>
      <mesh filename="meshes/gripper/left_inner_knuckle.STL"/>
    </geometry>
    <origin xyz="0 0 0" rpy="0 0 0"/>
    <material name="Gray"/>
  </visual>
  <collision>
    <geometry>
      <mesh filename="meshes/gripper/left_inner_knuckle.STL"/>
    </geometry>
    <origin xyz="0 0 0" rpy="0 0 0"/>
  </collision>
</link>

<!-- Left inner knuckle joint (mimic joint - follows main joint) -->
<joint name="left_inner_knuckle_joint" type="revolute">
  <parent link="base_link"/>
  <child link="left_inner_knuckle"/>
  <origin xyz="0.04 0 0.06" rpy="0 0 0"/>  <!-- Same as outer knuckle typically -->
  <axis xyz="0 0 1"/>
  <limit effort="20.0" lower="0" upper="0.8" velocity="2.0"/>
  <mimic joint="left_finger_joint" multiplier="1" offset="0"/>
  <dynamics damping="0.1" friction="0.1"/>
</joint>

<!-- Left Finger -->
<link name="left_finger">
  <inertial>
    <origin xyz="0 0 0" rpy="0 0 0"/>
    <mass value="0.02"/>
    <inertia ixx="0.0001" ixy="0" ixz="0" iyy="0.0001" iyz="0" izz="0.0001"/>
  </inertial>
  <visual>
    <geometry>
      <mesh filename="meshes/gripper/left_finger.STL"/>
    </geometry>
    <origin xyz="0 0 0" rpy="0 0 0"/>
    <material name="Gray"/>
  </visual>
  <collision>
    <geometry>
      <mesh filename="meshes/gripper/left_finger.STL"/>
    </geometry>
    <origin xyz="0 0 0" rpy="0 0 0"/>
  </collision>
</link>

<!-- Left finger tip joint -->
<joint name="left_finger_tip_joint" type="revolute">
  <parent link="left_outer_knuckle"/>
  <child link="left_finger"/>
  <origin xyz="0.05 0 0.04" rpy="0 0 0"/>  <!-- Adjust based on gripper geometry -->
  <axis xyz="0 0 1"/>
  <limit effort="20.0" lower="-0.8" upper="0" velocity="2.0"/>
  <mimic joint="left_finger_joint" multiplier="-1" offset="0"/>
  <dynamics damping="0.1" friction="0.1"/>
</joint>

<!-- RIGHT FINGER ASSEMBLY (Mirror of left) -->

<!-- Right Outer Knuckle -->
<link name="right_outer_knuckle">
  <inertial>
    <origin xyz="0 0 0" rpy="0 0 0"/>
    <mass value="0.05"/>
    <inertia ixx="0.0001" ixy="0" ixz="0" iyy="0.0001" iyz="0" izz="0.0001"/>
  </inertial>
  <visual>
    <geometry>
      <mesh filename="meshes/gripper/right_outer_knuckle.STL"/>
    </geometry>
    <origin xyz="0 0 0" rpy="0 0 0"/>
    <material name="Gray"/>
  </visual>
  <collision>
    <geometry>
      <mesh filename="meshes/gripper/right_outer_knuckle.STL"/>
    </geometry>
    <origin xyz="0 0 0" rpy="0 0 0"/>
  </collision>
</link>

<joint name="right_finger_joint" type="revolute">
  <parent link="base_link"/>
  <child link="right_outer_knuckle"/>
  <origin xyz="-0.04 0 0.06" rpy="0 0 3.14159265"/>  <!-- Mirror of left finger -->
  <axis xyz="0 0 1"/>  <!-- Opposite direction -->
  <limit effort="20.0" lower="0" upper="0.8" velocity="2.0"/>
  <mimic joint="left_finger_joint" multiplier="1" offset="0"/>
  <dynamics damping="0.1" friction="0.1"/>
</joint>

<!-- Right Inner Knuckle -->
<link name="right_inner_knuckle">
  <inertial>
    <origin xyz="0 0 0" rpy="0 0 0"/>
    <mass value="0.03"/>
    <inertia ixx="0.0001" ixy="0" ixz="0" iyy="0.0001" iyz="0" izz="0.0001"/>
  </inertial>
  <visual>
    <geometry>
      <mesh filename="meshes/gripper/right_inner_knuckle.STL"/>
    </geometry>
    <origin xyz="0 0 0" rpy="0 0 0"/>
    <material name="Gray"/>
  </visual>
  <collision>
    <geometry>
      <mesh filename="meshes/gripper/right_inner_knuckle.STL"/>
    </geometry>
    <origin xyz="0 0 0" rpy="0 0 0"/>
  </collision>
</link>

<!-- Right inner knuckle joint -->
<joint name="right_inner_knuckle_joint" type="revolute">
  <parent link="base_link"/>
  <child link="right_inner_knuckle"/>
  <origin xyz="-0.04 0 0.06" rpy="0 0 0"/>
  <axis xyz="0 0 -1"/>
  <limit effort="20.0" lower="0" upper="0.8" velocity="2.0"/>
  <mimic joint="left_finger_joint" multiplier="1" offset="0"/>
  <dynamics damping="0.1" friction="0.1"/>
</joint>

<!-- Right Finger -->
<link name="right_finger">
  <inertial>
    <origin xyz="0 0 0" rpy="0 0 0"/>
    <mass value="0.02"/>
    <inertia ixx="0.0001" ixy="0" ixz="0" iyy="0.0001" iyz="0" izz="0.0001"/>
  </inertial>
  <visual>
    <geometry>
      <mesh filename="meshes/gripper/right_finger.STL"/>
    </geometry>
    <origin xyz="0 0 0" rpy="0 0 0"/>
    <material name="Gray"/>
  </visual>
  <collision>
    <geometry>
      <mesh filename="meshes/gripper/right_finger.STL"/>
    </geometry>
    <origin xyz="0 0 0" rpy="0 0 0"/>
  </collision>
</link>

<!-- Right finger tip joint -->
<joint name="right_finger_tip_joint" type="revolute">
  <parent link="right_outer_knuckle"/>
  <child link="right_finger"/>
  <origin xyz="-0.05 0 0.04" rpy="0 0 0"/>  <!-- Mirror of left -->
  <axis xyz="0 0 -1"/>
  <limit effort="20.0" lower="-0.8" upper="0" velocity="2.0"/>
  <mimic joint="left_finger_joint" multiplier="-1" offset="0"/>
  <dynamics damping="0.1" friction="0.1"/>
</joint>

  <!-- STEP 5: Add transmission for gripper -->

<transmission name="gripper_transmission">
  <type>transmission_interface/SimpleTransmission</type>
  <joint name="left_finger_joint">
    <hardwareInterface>hardware_interface/PositionJointInterface</hardwareInterface>
  </joint>
  <actuator name="gripper_motor">
    <hardwareInterface>hardware_interface/PositionJointInterface</hardwareInterface>
    <mechanicalReduction>100</mechanicalReduction>
  </actuator>
</transmission>

  <transmission name="tran1">
    <type>transmission_interface/SimpleTransmission</type>
    <joint name="joint1">
      <hardwareInterface>hardware_interface/PositionJointInterface</hardwareInterface>
    </joint>
    <actuator name="motor1">
      <hardwareInterface>hardware_interface/PositionJointInterface</hardwareInterface>
      <mechanicalReduction>100</mechanicalReduction>
    </actuator>
  </transmission>
  <transmission name="tran2">
    <type>transmission_interface/SimpleTransmission</type>
    <joint name="joint2">
      <hardwareInterface>hardware_interface/PositionJointInterface</hardwareInterface>
    </joint>
    <actuator name="motor2">
      <hardwareInterface>hardware_interface/PositionJointInterface</hardwareInterface>
      <mechanicalReduction>100</mechanicalReduction>
    </actuator>
  </transmission>
  <transmission name="tran3">
    <type>transmission_interface/SimpleTransmission</type>
    <joint name="joint3">
      <hardwareInterface>hardware_interface/PositionJointInterface</hardwareInterface>
    </joint>
    <actuator name="motor3">
      <hardwareInterface>hardware_interface/PositionJointInterface</hardwareInterface>
      <mechanicalReduction>100</mechanicalReduction>
    </actuator>
  </transmission>
  <transmission name="tran4">
    <type>transmission_interface/SimpleTransmission</type>
    <joint name="joint4">
      <hardwareInterface>hardware_interface/PositionJointInterface</hardwareInterface>
    </joint>
    <actuator name="motor3">
      <hardwareInterface>hardware_interface/PositionJointInterface</hardwareInterface>
      <mechanicalReduction>100</mechanicalReduction>
    </actuator>
  </transmission>
  <transmission name="tran5">
    <type>transmission_interface/SimpleTransmission</type>
    <joint name="joint5">
      <hardwareInterface>hardware_interface/PositionJointInterface</hardwareInterface>
    </joint>
    <actuator name="motor5">
      <hardwareInterface>hardware_interface/PositionJointInterface</hardwareInterface>
      <mechanicalReduction>100</mechanicalReduction>
    </actuator>
  </transmission>
  <transmission name="tran6">
    <type>transmission_interface/SimpleTransmission</type>
    <joint name="joint6">
      <hardwareInterface>hardware_interface/PositionJointInterface</hardwareInterface>
    </joint>
    <actuator name="motor6">
      <hardwareInterface>hardware_interface/PositionJointInterface</hardwareInterface>
      <mechanicalReduction>100</mechanicalReduction>
    </actuator>
  </transmission>
  <gazebo reference="link_base">
    <selfCollide>true</selfCollide>
  </gazebo>
  <gazebo reference="link1">
    <selfCollide>true</selfCollide>
  </gazebo>
  <gazebo reference="link2">
    <selfCollide>true</selfCollide>
  </gazebo>
  <gazebo reference="link3">
    <selfCollide>true</selfCollide>
  </gazebo>
  <gazebo reference="link4">
    <selfCollide>true</selfCollide>
  </gazebo>
  <gazebo reference="link5">
    <selfCollide>true</selfCollide>
  </gazebo>
  <gazebo reference="link6">
    <selfCollide>true</selfCollide>
  </gazebo>
  <gazebo reference="base_link">
  <selfCollide>true</selfCollide>
</gazebo>
  <!-- <gazebo reference="left_outer_knuckle">
    <selfCollide>true</selfCollide>
  </gazebo>
  <gazebo reference="left_inner_knuckle">
    <selfCollide>true</selfCollide>
  </gazebo>
  <gazebo reference="left_finger">
    <selfCollide>true</selfCollide>
  </gazebo>
  <gazebo reference="right_outer_knuckle">
    <selfCollide>true</selfCollide>
  </gazebo>
  <gazebo reference="right_inner_knuckle">
    <selfCollide>true</selfCollide>
  </gazebo>
  <gazebo reference="right_finger">
    <selfCollide>true</selfCollide>
  </gazebo> -->

  <link name="link_eef"/>
  <joint name="joint_eef" type="fixed">
    <origin rpy="0 0 0" xyz="0 0 0"/>
    <parent link="link6"/>
    <child link="link_eef"/>
  </joint>
  
  <gazebo>
    <plugin filename="libgazebo_ros2_control.so" name="gazebo_ros2_control">
      <robot_sim_type>gazebo_ros2_control/GazeboSystem</robot_sim_type>
      <parameters>/home/rad/Code/lite6_ws/install/xarm_controller/share/xarm_controller/config/lite6_controllers.yaml</parameters>
    </plugin>
  </gazebo>
  <!-- Insert at the end of xarm_device_macro.xacro -->
</robot>

